{
 "cells": [
  {
   "cell_type": "code",
   "execution_count": 1,
   "metadata": {},
   "outputs": [],
   "source": [
    "url = \"https://raw.githubusercontent.com/chiarorosa/ia_aprendizado_maquina_basico/main/ml-dataset/kaggle-basico/attrition_Rate_Company.csv\"\n",
    "\n",
    "import pandas as pd\n",
    "from sklearn.model_selection import train_test_split\n",
    "from sklearn.metrics import accuracy_score # Avaliação de Acurácia\n",
    "from sklearn.preprocessing import StandardScaler,LabelEncoder\n",
    "from sklearn.linear_model import SGDClassifier\n",
    "from sklearn.model_selection import RandomizedSearchCV\n",
    "import numpy as np\n"
   ]
  },
  {
   "cell_type": "code",
   "execution_count": 2,
   "metadata": {},
   "outputs": [],
   "source": [
    "df = pd.read_csv(url)\n",
    "df.head()\n",
    "\n",
    "df.dropna(inplace=True)\n",
    "\n",
    "labelEnconder = LabelEncoder()\n",
    "categorizacaoColunas = ['BusinessTravel', 'EducationField', 'Department', 'Gender', 'JobRole', 'MaritalStatus','Attrition','Over18']\n",
    "\n",
    "for coluna in categorizacaoColunas:\n",
    "    df[coluna] = labelEnconder.fit_transform(df[coluna])\n",
    "    \n",
    "X = df.drop('Attrition', axis=1)\n",
    "y = df['Attrition']\n",
    "\n",
    "\n",
    "\n",
    "\n",
    "\n"
   ]
  },
  {
   "cell_type": "code",
   "execution_count": 3,
   "metadata": {},
   "outputs": [],
   "source": [
    "scaler = StandardScaler()\n",
    "x_scaled = scaler.fit_transform(X)\n",
    "\n",
    "\n",
    "# Dividir em dois conjuntos, treinamento e teste, usando pareto 80/20\n",
    "X_train, X_test, y_train, y_test = train_test_split(\n",
    "    x_scaled,\n",
    "    y,\n",
    "    test_size=0.2, # pareto\n",
    "    random_state=42 # reproduzivel\n",
    ")"
   ]
  },
  {
   "cell_type": "code",
   "execution_count": 6,
   "metadata": {},
   "outputs": [
    {
     "name": "stdout",
     "output_type": "stream",
     "text": [
      "Acurácia: 83.37\n",
      "Melhor modelo: SGDClassifier(alpha=0.0007818181818181819, epsilon=0.4, eta0=0.001,\n",
      "              learning_rate='adaptive', max_iter=3700, power_t=0.6)\n",
      "Parâmetros do melhor modelo: {'power_t': 0.6, 'max_iter': 3700, 'loss': 'hinge', 'learning_rate': 'adaptive', 'fit_intercept': True, 'eta0': 0.001, 'epsilon': 0.4, 'alpha': 0.0007818181818181819}\n",
      "Acurácia anterior: 83.37\n",
      "Acurácia atualizada: 83.37\n"
     ]
    },
    {
     "name": "stderr",
     "output_type": "stream",
     "text": [
      "c:\\Users\\Pedro\\AppData\\Local\\Programs\\Python\\Python311\\Lib\\site-packages\\sklearn\\model_selection\\_validation.py:547: FitFailedWarning: \n",
      "30 fits failed out of a total of 100.\n",
      "The score on these train-test partitions for these parameters will be set to nan.\n",
      "If these failures are not expected, you can try to debug them by setting error_score='raise'.\n",
      "\n",
      "Below are more details about the failures:\n",
      "--------------------------------------------------------------------------------\n",
      "4 fits failed with the following error:\n",
      "Traceback (most recent call last):\n",
      "  File \"c:\\Users\\Pedro\\AppData\\Local\\Programs\\Python\\Python311\\Lib\\site-packages\\sklearn\\model_selection\\_validation.py\", line 895, in _fit_and_score\n",
      "    estimator.fit(X_train, y_train, **fit_params)\n",
      "  File \"c:\\Users\\Pedro\\AppData\\Local\\Programs\\Python\\Python311\\Lib\\site-packages\\sklearn\\base.py\", line 1467, in wrapper\n",
      "    estimator._validate_params()\n",
      "  File \"c:\\Users\\Pedro\\AppData\\Local\\Programs\\Python\\Python311\\Lib\\site-packages\\sklearn\\base.py\", line 666, in _validate_params\n",
      "    validate_parameter_constraints(\n",
      "  File \"c:\\Users\\Pedro\\AppData\\Local\\Programs\\Python\\Python311\\Lib\\site-packages\\sklearn\\utils\\_param_validation.py\", line 95, in validate_parameter_constraints\n",
      "    raise InvalidParameterError(\n",
      "sklearn.utils._param_validation.InvalidParameterError: The 'loss' parameter of SGDClassifier must be a str among {'perceptron', 'modified_huber', 'huber', 'squared_hinge', 'squared_epsilon_insensitive', 'log_loss', 'epsilon_insensitive', 'squared_error', 'hinge'}. Got 'squared_loss' instead.\n",
      "\n",
      "--------------------------------------------------------------------------------\n",
      "3 fits failed with the following error:\n",
      "Traceback (most recent call last):\n",
      "  File \"c:\\Users\\Pedro\\AppData\\Local\\Programs\\Python\\Python311\\Lib\\site-packages\\sklearn\\model_selection\\_validation.py\", line 895, in _fit_and_score\n",
      "    estimator.fit(X_train, y_train, **fit_params)\n",
      "  File \"c:\\Users\\Pedro\\AppData\\Local\\Programs\\Python\\Python311\\Lib\\site-packages\\sklearn\\base.py\", line 1467, in wrapper\n",
      "    estimator._validate_params()\n",
      "  File \"c:\\Users\\Pedro\\AppData\\Local\\Programs\\Python\\Python311\\Lib\\site-packages\\sklearn\\base.py\", line 666, in _validate_params\n",
      "    validate_parameter_constraints(\n",
      "  File \"c:\\Users\\Pedro\\AppData\\Local\\Programs\\Python\\Python311\\Lib\\site-packages\\sklearn\\utils\\_param_validation.py\", line 95, in validate_parameter_constraints\n",
      "    raise InvalidParameterError(\n",
      "sklearn.utils._param_validation.InvalidParameterError: The 'loss' parameter of SGDClassifier must be a str among {'squared_epsilon_insensitive', 'modified_huber', 'perceptron', 'log_loss', 'squared_error', 'epsilon_insensitive', 'huber', 'hinge', 'squared_hinge'}. Got 'squared_loss' instead.\n",
      "\n",
      "--------------------------------------------------------------------------------\n",
      "4 fits failed with the following error:\n",
      "Traceback (most recent call last):\n",
      "  File \"c:\\Users\\Pedro\\AppData\\Local\\Programs\\Python\\Python311\\Lib\\site-packages\\sklearn\\model_selection\\_validation.py\", line 895, in _fit_and_score\n",
      "    estimator.fit(X_train, y_train, **fit_params)\n",
      "  File \"c:\\Users\\Pedro\\AppData\\Local\\Programs\\Python\\Python311\\Lib\\site-packages\\sklearn\\base.py\", line 1467, in wrapper\n",
      "    estimator._validate_params()\n",
      "  File \"c:\\Users\\Pedro\\AppData\\Local\\Programs\\Python\\Python311\\Lib\\site-packages\\sklearn\\base.py\", line 666, in _validate_params\n",
      "    validate_parameter_constraints(\n",
      "  File \"c:\\Users\\Pedro\\AppData\\Local\\Programs\\Python\\Python311\\Lib\\site-packages\\sklearn\\utils\\_param_validation.py\", line 95, in validate_parameter_constraints\n",
      "    raise InvalidParameterError(\n",
      "sklearn.utils._param_validation.InvalidParameterError: The 'loss' parameter of SGDClassifier must be a str among {'log_loss', 'epsilon_insensitive', 'hinge', 'perceptron', 'modified_huber', 'huber', 'squared_error', 'squared_hinge', 'squared_epsilon_insensitive'}. Got 'squared_loss' instead.\n",
      "\n",
      "--------------------------------------------------------------------------------\n",
      "2 fits failed with the following error:\n",
      "Traceback (most recent call last):\n",
      "  File \"c:\\Users\\Pedro\\AppData\\Local\\Programs\\Python\\Python311\\Lib\\site-packages\\sklearn\\model_selection\\_validation.py\", line 895, in _fit_and_score\n",
      "    estimator.fit(X_train, y_train, **fit_params)\n",
      "  File \"c:\\Users\\Pedro\\AppData\\Local\\Programs\\Python\\Python311\\Lib\\site-packages\\sklearn\\base.py\", line 1467, in wrapper\n",
      "    estimator._validate_params()\n",
      "  File \"c:\\Users\\Pedro\\AppData\\Local\\Programs\\Python\\Python311\\Lib\\site-packages\\sklearn\\base.py\", line 666, in _validate_params\n",
      "    validate_parameter_constraints(\n",
      "  File \"c:\\Users\\Pedro\\AppData\\Local\\Programs\\Python\\Python311\\Lib\\site-packages\\sklearn\\utils\\_param_validation.py\", line 95, in validate_parameter_constraints\n",
      "    raise InvalidParameterError(\n",
      "sklearn.utils._param_validation.InvalidParameterError: The 'loss' parameter of SGDClassifier must be a str among {'log_loss', 'squared_hinge', 'modified_huber', 'squared_error', 'squared_epsilon_insensitive', 'epsilon_insensitive', 'huber', 'perceptron', 'hinge'}. Got 'squared_loss' instead.\n",
      "\n",
      "--------------------------------------------------------------------------------\n",
      "3 fits failed with the following error:\n",
      "Traceback (most recent call last):\n",
      "  File \"c:\\Users\\Pedro\\AppData\\Local\\Programs\\Python\\Python311\\Lib\\site-packages\\sklearn\\model_selection\\_validation.py\", line 895, in _fit_and_score\n",
      "    estimator.fit(X_train, y_train, **fit_params)\n",
      "  File \"c:\\Users\\Pedro\\AppData\\Local\\Programs\\Python\\Python311\\Lib\\site-packages\\sklearn\\base.py\", line 1467, in wrapper\n",
      "    estimator._validate_params()\n",
      "  File \"c:\\Users\\Pedro\\AppData\\Local\\Programs\\Python\\Python311\\Lib\\site-packages\\sklearn\\base.py\", line 666, in _validate_params\n",
      "    validate_parameter_constraints(\n",
      "  File \"c:\\Users\\Pedro\\AppData\\Local\\Programs\\Python\\Python311\\Lib\\site-packages\\sklearn\\utils\\_param_validation.py\", line 95, in validate_parameter_constraints\n",
      "    raise InvalidParameterError(\n",
      "sklearn.utils._param_validation.InvalidParameterError: The 'loss' parameter of SGDClassifier must be a str among {'hinge', 'log_loss', 'squared_epsilon_insensitive', 'squared_error', 'huber', 'modified_huber', 'squared_hinge', 'epsilon_insensitive', 'perceptron'}. Got 'squared_loss' instead.\n",
      "\n",
      "--------------------------------------------------------------------------------\n",
      "3 fits failed with the following error:\n",
      "Traceback (most recent call last):\n",
      "  File \"c:\\Users\\Pedro\\AppData\\Local\\Programs\\Python\\Python311\\Lib\\site-packages\\sklearn\\model_selection\\_validation.py\", line 895, in _fit_and_score\n",
      "    estimator.fit(X_train, y_train, **fit_params)\n",
      "  File \"c:\\Users\\Pedro\\AppData\\Local\\Programs\\Python\\Python311\\Lib\\site-packages\\sklearn\\base.py\", line 1467, in wrapper\n",
      "    estimator._validate_params()\n",
      "  File \"c:\\Users\\Pedro\\AppData\\Local\\Programs\\Python\\Python311\\Lib\\site-packages\\sklearn\\base.py\", line 666, in _validate_params\n",
      "    validate_parameter_constraints(\n",
      "  File \"c:\\Users\\Pedro\\AppData\\Local\\Programs\\Python\\Python311\\Lib\\site-packages\\sklearn\\utils\\_param_validation.py\", line 95, in validate_parameter_constraints\n",
      "    raise InvalidParameterError(\n",
      "sklearn.utils._param_validation.InvalidParameterError: The 'loss' parameter of SGDClassifier must be a str among {'hinge', 'squared_error', 'huber', 'log_loss', 'modified_huber', 'epsilon_insensitive', 'squared_hinge', 'perceptron', 'squared_epsilon_insensitive'}. Got 'squared_loss' instead.\n",
      "\n",
      "--------------------------------------------------------------------------------\n",
      "2 fits failed with the following error:\n",
      "Traceback (most recent call last):\n",
      "  File \"c:\\Users\\Pedro\\AppData\\Local\\Programs\\Python\\Python311\\Lib\\site-packages\\sklearn\\model_selection\\_validation.py\", line 895, in _fit_and_score\n",
      "    estimator.fit(X_train, y_train, **fit_params)\n",
      "  File \"c:\\Users\\Pedro\\AppData\\Local\\Programs\\Python\\Python311\\Lib\\site-packages\\sklearn\\base.py\", line 1467, in wrapper\n",
      "    estimator._validate_params()\n",
      "  File \"c:\\Users\\Pedro\\AppData\\Local\\Programs\\Python\\Python311\\Lib\\site-packages\\sklearn\\base.py\", line 666, in _validate_params\n",
      "    validate_parameter_constraints(\n",
      "  File \"c:\\Users\\Pedro\\AppData\\Local\\Programs\\Python\\Python311\\Lib\\site-packages\\sklearn\\utils\\_param_validation.py\", line 95, in validate_parameter_constraints\n",
      "    raise InvalidParameterError(\n",
      "sklearn.utils._param_validation.InvalidParameterError: The 'loss' parameter of SGDClassifier must be a str among {'squared_epsilon_insensitive', 'log_loss', 'hinge', 'modified_huber', 'epsilon_insensitive', 'squared_error', 'huber', 'perceptron', 'squared_hinge'}. Got 'squared_loss' instead.\n",
      "\n",
      "--------------------------------------------------------------------------------\n",
      "1 fits failed with the following error:\n",
      "Traceback (most recent call last):\n",
      "  File \"c:\\Users\\Pedro\\AppData\\Local\\Programs\\Python\\Python311\\Lib\\site-packages\\sklearn\\model_selection\\_validation.py\", line 895, in _fit_and_score\n",
      "    estimator.fit(X_train, y_train, **fit_params)\n",
      "  File \"c:\\Users\\Pedro\\AppData\\Local\\Programs\\Python\\Python311\\Lib\\site-packages\\sklearn\\base.py\", line 1467, in wrapper\n",
      "    estimator._validate_params()\n",
      "  File \"c:\\Users\\Pedro\\AppData\\Local\\Programs\\Python\\Python311\\Lib\\site-packages\\sklearn\\base.py\", line 666, in _validate_params\n",
      "    validate_parameter_constraints(\n",
      "  File \"c:\\Users\\Pedro\\AppData\\Local\\Programs\\Python\\Python311\\Lib\\site-packages\\sklearn\\utils\\_param_validation.py\", line 95, in validate_parameter_constraints\n",
      "    raise InvalidParameterError(\n",
      "sklearn.utils._param_validation.InvalidParameterError: The 'loss' parameter of SGDClassifier must be a str among {'perceptron', 'squared_error', 'squared_hinge', 'hinge', 'squared_epsilon_insensitive', 'huber', 'log_loss', 'modified_huber', 'epsilon_insensitive'}. Got 'squared_loss' instead.\n",
      "\n",
      "--------------------------------------------------------------------------------\n",
      "2 fits failed with the following error:\n",
      "Traceback (most recent call last):\n",
      "  File \"c:\\Users\\Pedro\\AppData\\Local\\Programs\\Python\\Python311\\Lib\\site-packages\\sklearn\\model_selection\\_validation.py\", line 895, in _fit_and_score\n",
      "    estimator.fit(X_train, y_train, **fit_params)\n",
      "  File \"c:\\Users\\Pedro\\AppData\\Local\\Programs\\Python\\Python311\\Lib\\site-packages\\sklearn\\base.py\", line 1467, in wrapper\n",
      "    estimator._validate_params()\n",
      "  File \"c:\\Users\\Pedro\\AppData\\Local\\Programs\\Python\\Python311\\Lib\\site-packages\\sklearn\\base.py\", line 666, in _validate_params\n",
      "    validate_parameter_constraints(\n",
      "  File \"c:\\Users\\Pedro\\AppData\\Local\\Programs\\Python\\Python311\\Lib\\site-packages\\sklearn\\utils\\_param_validation.py\", line 95, in validate_parameter_constraints\n",
      "    raise InvalidParameterError(\n",
      "sklearn.utils._param_validation.InvalidParameterError: The 'loss' parameter of SGDClassifier must be a str among {'hinge', 'log_loss', 'epsilon_insensitive', 'modified_huber', 'squared_hinge', 'squared_error', 'huber', 'squared_epsilon_insensitive', 'perceptron'}. Got 'squared_loss' instead.\n",
      "\n",
      "--------------------------------------------------------------------------------\n",
      "2 fits failed with the following error:\n",
      "Traceback (most recent call last):\n",
      "  File \"c:\\Users\\Pedro\\AppData\\Local\\Programs\\Python\\Python311\\Lib\\site-packages\\sklearn\\model_selection\\_validation.py\", line 895, in _fit_and_score\n",
      "    estimator.fit(X_train, y_train, **fit_params)\n",
      "  File \"c:\\Users\\Pedro\\AppData\\Local\\Programs\\Python\\Python311\\Lib\\site-packages\\sklearn\\base.py\", line 1467, in wrapper\n",
      "    estimator._validate_params()\n",
      "  File \"c:\\Users\\Pedro\\AppData\\Local\\Programs\\Python\\Python311\\Lib\\site-packages\\sklearn\\base.py\", line 666, in _validate_params\n",
      "    validate_parameter_constraints(\n",
      "  File \"c:\\Users\\Pedro\\AppData\\Local\\Programs\\Python\\Python311\\Lib\\site-packages\\sklearn\\utils\\_param_validation.py\", line 95, in validate_parameter_constraints\n",
      "    raise InvalidParameterError(\n",
      "sklearn.utils._param_validation.InvalidParameterError: The 'loss' parameter of SGDClassifier must be a str among {'log_loss', 'squared_hinge', 'modified_huber', 'squared_error', 'squared_epsilon_insensitive', 'epsilon_insensitive', 'huber', 'perceptron', 'hinge'}. Got 'log' instead.\n",
      "\n",
      "--------------------------------------------------------------------------------\n",
      "2 fits failed with the following error:\n",
      "Traceback (most recent call last):\n",
      "  File \"c:\\Users\\Pedro\\AppData\\Local\\Programs\\Python\\Python311\\Lib\\site-packages\\sklearn\\model_selection\\_validation.py\", line 895, in _fit_and_score\n",
      "    estimator.fit(X_train, y_train, **fit_params)\n",
      "  File \"c:\\Users\\Pedro\\AppData\\Local\\Programs\\Python\\Python311\\Lib\\site-packages\\sklearn\\base.py\", line 1467, in wrapper\n",
      "    estimator._validate_params()\n",
      "  File \"c:\\Users\\Pedro\\AppData\\Local\\Programs\\Python\\Python311\\Lib\\site-packages\\sklearn\\base.py\", line 666, in _validate_params\n",
      "    validate_parameter_constraints(\n",
      "  File \"c:\\Users\\Pedro\\AppData\\Local\\Programs\\Python\\Python311\\Lib\\site-packages\\sklearn\\utils\\_param_validation.py\", line 95, in validate_parameter_constraints\n",
      "    raise InvalidParameterError(\n",
      "sklearn.utils._param_validation.InvalidParameterError: The 'loss' parameter of SGDClassifier must be a str among {'hinge', 'squared_error', 'huber', 'log_loss', 'modified_huber', 'epsilon_insensitive', 'squared_hinge', 'perceptron', 'squared_epsilon_insensitive'}. Got 'log' instead.\n",
      "\n",
      "--------------------------------------------------------------------------------\n",
      "1 fits failed with the following error:\n",
      "Traceback (most recent call last):\n",
      "  File \"c:\\Users\\Pedro\\AppData\\Local\\Programs\\Python\\Python311\\Lib\\site-packages\\sklearn\\model_selection\\_validation.py\", line 895, in _fit_and_score\n",
      "    estimator.fit(X_train, y_train, **fit_params)\n",
      "  File \"c:\\Users\\Pedro\\AppData\\Local\\Programs\\Python\\Python311\\Lib\\site-packages\\sklearn\\base.py\", line 1467, in wrapper\n",
      "    estimator._validate_params()\n",
      "  File \"c:\\Users\\Pedro\\AppData\\Local\\Programs\\Python\\Python311\\Lib\\site-packages\\sklearn\\base.py\", line 666, in _validate_params\n",
      "    validate_parameter_constraints(\n",
      "  File \"c:\\Users\\Pedro\\AppData\\Local\\Programs\\Python\\Python311\\Lib\\site-packages\\sklearn\\utils\\_param_validation.py\", line 95, in validate_parameter_constraints\n",
      "    raise InvalidParameterError(\n",
      "sklearn.utils._param_validation.InvalidParameterError: The 'loss' parameter of SGDClassifier must be a str among {'squared_epsilon_insensitive', 'log_loss', 'hinge', 'modified_huber', 'epsilon_insensitive', 'squared_error', 'huber', 'perceptron', 'squared_hinge'}. Got 'log' instead.\n",
      "\n",
      "--------------------------------------------------------------------------------\n",
      "1 fits failed with the following error:\n",
      "Traceback (most recent call last):\n",
      "  File \"c:\\Users\\Pedro\\AppData\\Local\\Programs\\Python\\Python311\\Lib\\site-packages\\sklearn\\model_selection\\_validation.py\", line 895, in _fit_and_score\n",
      "    estimator.fit(X_train, y_train, **fit_params)\n",
      "  File \"c:\\Users\\Pedro\\AppData\\Local\\Programs\\Python\\Python311\\Lib\\site-packages\\sklearn\\base.py\", line 1467, in wrapper\n",
      "    estimator._validate_params()\n",
      "  File \"c:\\Users\\Pedro\\AppData\\Local\\Programs\\Python\\Python311\\Lib\\site-packages\\sklearn\\base.py\", line 666, in _validate_params\n",
      "    validate_parameter_constraints(\n",
      "  File \"c:\\Users\\Pedro\\AppData\\Local\\Programs\\Python\\Python311\\Lib\\site-packages\\sklearn\\utils\\_param_validation.py\", line 95, in validate_parameter_constraints\n",
      "    raise InvalidParameterError(\n",
      "sklearn.utils._param_validation.InvalidParameterError: The 'loss' parameter of SGDClassifier must be a str among {'squared_epsilon_insensitive', 'perceptron', 'squared_hinge', 'log_loss', 'hinge', 'epsilon_insensitive', 'modified_huber', 'squared_error', 'huber'}. Got 'squared_loss' instead.\n",
      "\n",
      "  warnings.warn(some_fits_failed_message, FitFailedWarning)\n",
      "c:\\Users\\Pedro\\AppData\\Local\\Programs\\Python\\Python311\\Lib\\site-packages\\sklearn\\model_selection\\_search.py:1051: UserWarning: One or more of the test scores are non-finite: [0.56860465        nan 0.5622093  0.56424419        nan        nan\n",
      " 0.52034884 0.83837209        nan 0.83924419 0.56598837 0.78372093\n",
      " 0.56511628 0.83953488        nan        nan 0.53982558 0.83953488\n",
      " 0.83953488 0.53284884]\n",
      "  warnings.warn(\n"
     ]
    }
   ],
   "source": [
    "grade = {\n",
    "    'loss': [\n",
    "        'hinge', 'log', 'modified_huber', 'squared_hinge', 'perceptron', \n",
    "        'squared_loss', 'huber', 'epsilon_insensitive', 'squared_epsilon_insensitive'\n",
    "    ],\n",
    "    'alpha': np.linspace(0.0001, 0.001, 100),\n",
    "    'fit_intercept': [True, False],\n",
    "    'max_iter': np.arange(1000, 10000, 100),\n",
    "    'learning_rate': ['constant', 'optimal', 'invscaling', 'adaptive'],\n",
    "    'eta0': np.logspace(-4, 0, 5),  # Taxa de aprendizado inicial\n",
    "    'power_t': np.linspace(0.1, 1, 10),  # Exponente para taxa de aprendizado inverso\n",
    "    'epsilon': np.linspace(0.1, 1, 10),  # Relevante para algumas funções de perda\n",
    "}\n",
    "\n",
    "SGD = RandomizedSearchCV(\n",
    "    SGDClassifier(),\n",
    "    grade,\n",
    "    cv=5,\n",
    "    scoring='accuracy',\n",
    "    n_iter=20,  # Número de iterações de busca aleatória\n",
    "    n_jobs=-1,  # Use todos os núcleos disponíveis\n",
    "    random_state=42  # Para reprodutibilidade\n",
    ")\n",
    "\n",
    "SGD.fit(X_train, y_train)\n",
    "\n",
    "melhor = SGD.best_estimator_\n",
    "\n",
    "y_pred = melhor.predict(X_test)\n",
    "\n",
    "acuracia = accuracy_score(y_test, y_pred)\n",
    "\n",
    "print(f'Acurácia: {acuracia * 100:.2f}')\n",
    "print(f'Melhor modelo: {melhor}')\n",
    "print(f'Parâmetros do melhor modelo: {SGD.best_params_}')\n",
    "\n",
    "guardaAcc = 0\n",
    "\n",
    "with open('Melhor Acurracia SGD.txt', 'r+', encoding='utf-8') as f:\n",
    "        try:\n",
    "            linha = f.readline().strip()\n",
    "            if linha.startswith('Acurácia:'):\n",
    "                guardaAcc = float(linha.split(': ')[1]) / 100\n",
    "                print(f'Acurácia anterior: {guardaAcc * 100:.2f}')\n",
    "                if acuracia > guardaAcc:\n",
    "                    f.seek(0) # vai pro inicio\n",
    "                    f.write(f'Acurácia: {acuracia * 100:.2f} \\n')\n",
    "                    \n",
    "                    f.truncate() #  remove residuos antigos\n",
    "                    print(f'Acurácia atualizada: {acuracia * 100:.2f}')\n",
    "                else:\n",
    "                    print('Acurácia não atualizada')\n",
    "        except Exception as e:\n",
    "            print(f\"Erro ao ler o arquivo: {e}\")\n",
    "       \n"
   ]
  }
 ],
 "metadata": {
  "kernelspec": {
   "display_name": "Python 3",
   "language": "python",
   "name": "python3"
  },
  "language_info": {
   "codemirror_mode": {
    "name": "ipython",
    "version": 3
   },
   "file_extension": ".py",
   "mimetype": "text/x-python",
   "name": "python",
   "nbconvert_exporter": "python",
   "pygments_lexer": "ipython3",
   "version": "3.11.5"
  }
 },
 "nbformat": 4,
 "nbformat_minor": 2
}
